Workbook

Sheet Deliverables
A1: Activation Analysis
A2: Instructions: In Course 1, you learned how to acquire a customer. Now you have driven your prospect to the point of signup, this prospect is handed off from the Growth PM focused on acquisition to Growth PM focused on activation, YOU.
A4: =HYPERLINK("https://app.productboard.com/register","Step 1: Complete Tabs 1 - 2 in order by signing up for the free trial of productboard: https://app.productboard.com/register. ") -> Step 1: Complete Tabs 1 - 2 in order by signing up for the free trial of productboard: https://app.productboard.com/register.
A5: These tasks will help you understand how to decrease time-to-value and remove friction for users when signing up. After signing up, it's important to activate customers so they experience your value proposition as early as possible, so we must activate users quickly.
A6: Step 2: Complete Tabs 3 - 8 in order by signing up for Slack: https://slack.com/get-started. These tasks will help you understand how to apply activation theories to guide users from 1-stage to another (signup to engagement) in the Activation model and how to segment audiences and use levers to increase engagement. You are using two different companies (Slack and Productboard) in the project because it will allow you to apply the frameworks, theories, and methods in the classroom to multiple examples, seeing how a GPM at a large and a small scale company address signup flow and activation.
A7: These tasks will help you understand how to apply activation theories to guide users from 1-stage to another (signup to engagement) in the Activation flow, how to segment audiences and use levers to increase engagement.
A8: You are using two different companies (Slack and Productboard) in the project because it will allow you to apply the frameworks, theories, and methods in the classroom to multiple contexts. You will get a feeling for how a GPM at a large and a small scale company address signup flow and activation.
A9: Note: If you are unable to or have not used Slack before, imagine a product that is the equivalent to SMS, Messenger, or Whatsapp, but for business use-case. Think of the tools mentioned above as an equivalent if you are unable to think of the moments for Slack.
A10: Mark a task completed on Column B after completing each Tab. To help you keep track of what you have completed.
A12: Tab | B12: Completed? | C12: Tasks
C13: Signup Flow
A14: 1 | B14: FALSE | C14: Measure drop-offs
A15: 2 | B15: FALSE | C15: Signup Experiments
C16: Understand Product
A17: 3 | B17: FALSE | C17: Activation Hypothesis
C18: Funnel Analysis
A19: 4 | B19: FALSE | C19: Habit Moment and Metric Analysis
A20: 5 | B20: FALSE | C20: Aha Moment and Metric Analysis
A21: 6 | B21: FALSE | C21: Setup Moment and Metric Analysis
A22: 7 | B22: FALSE | C22: Activation Funnel
C23: Activation by Segment
A24: 8 | B24: FALSE | C24: Segment Analysis

Sheet Tab 1 - Measure drop-offs
A1: Measure drop-offs
A3: Scenario: You have been brought onto a project at Productboard to help the company optimize the signup flow.
A5: Your task is to analyze each step in the sign up flow that a user would go through.
A6: Qualitatively, understand what each step is asking and if it creates any bad friction.
A7: Quantitatively, measure the amount of input (click and fields) it takes for the user to complete each step and what the drop-off rates are.
A8: Once you understand the existing flow, suggest experiments to reduce drop-offs %. Doing so, you will increase the amount of leads to the top of the funnel.
A9: Skill: You should: (1) Calculate drop-offs at each step of sign up flow (2) Analyze how to reduce drop-offs (increase the signup completion rate) in the flow (3) Think on how to get users through the activation funnel (4) Create experiments using the [ACTION], [OUTCOME], and [THEORY] framework.
A10: Instructions: Sign Up for the free trial of productboard (https://app.productboard.com/register) to complete in-order, a row-at-a-time, the 9 sign-up steps in Column A. Each screen in the sign up on productboard will equal a row in this sheet. Pause at each screen on signup to complete the analysis on each row in this sheet by filling in the questions in the columns for that step before continuing with your sign up on productboard. Along the way, address the questions and calculations in Row 20 to explain your understanding of friction in each step and suggest experiments to address any frictions. Complete the task 1-row at a time from Row 22 - 29.
A11: 1. Take the Click Through # and calculate the fields on Column D, E, and F.
A12: 2. Fill in the # of clicks and fields in Column G and H as you go through each step of the sign up flow.
A13: 3. In Column M and N, take the CTA directly from the sign-up flow and document the CTA and an explanation of the information that is being asked
A14: 4. In Column O explain your understanding of the value extracted from the information collected.
... A18: Cells in Orange have been completed for you as an example. The formulas have been removed.
A19: A | B19: B | C19: C | D19: D | E19: E | F19: F | G19: G | H19: H | I19: I | J19: J | K19: K | L19: L | M19: M | N19: N | O19: O | P19: P | Q19: Q | R19: R | S19: S | T19: T | U19: U | V19: V | W19: W
A20: Step | B20: Name | C20: Click-through # | D20: Click-through % | E20: Drop-off % at each step | F20: Drop-off % through funnel (starting signup) | G20: How many total clicks to get to next step? (including optional fields) | H20: How many fields to fill out? (including optional fields) | I20: Observations (Personal Notes) | M20: What is the Call-To-Action (CTA)? | N20: What information is being asked on this step? | O20: What do you think this information is used for? | P20: Is the action clear? (If not, explain) | Q20: Do you think this step is located in the correct (most natural) order of the flow? (If not, explain) | R20: Is this step necessary? (If not, explain) | S20: Is this good friction or bad friction? | T20: If bad friction, how can it be addressed? | U20: Why might you not want to remove this bad friction? | V20: Can the amount of clicks be reduced? If so, how? | W20: Experiment Brief
A21: 1 | B21: Home Page | C21: =3820*2 -> 7640 | D21: 0.1102 | E21: 0.8898 | F21: 0%% | G21: 1 | H21: 0 | I21: Just a simple home page with 2 call-to-actions (CTAs) above the fold. | M21: [Try Now] and [TRY NOW] | N21: To start the free trial by clicking the CTA | O21: To start the free trial | P21: Yes | Q21: Yes | R21: Yes | S21: Good | T21: -- | W21: [ACTION] If we run an a/b experiment by changing the copy from "try now" to "start free trial", or "start 14-day trial" [OUTCOME] we can evaluate if there is more click-throughs to the sign-up page [Theory] because the copy will better present that the trial is offered for free, is for 14-days, and does not require a credit card.
A22: 2 | B22: Free Trial Sign Up | C22: =421*2 -> 842 | D22: =C23/C22 -> 0.93586698 | E22: =1-D22 -> 0.064133017 | F22: =1-(C23/$C$22) -> 0.064133017 | G22: 3 | H22: 1 | I22: one field (email address to fill) and one CTA at the buttom | M22: Sign up with work email | N22: Start the sign up process by providing the Email Address | O22: to start the sign up process | P22: Yes | Q22: Yes | R22: Yes | S22: Good | T22: -- | U22: - | V22: No | W22: [ACTION] If we run an a/b experiment by changing the copy from "Sign up with work email" to "Get Verification Link", [OUTCOME] we can test whether this CTA copy performs better or leave the first one [Theory] because this new copy can remove some uncertainty and inform the user about the next step and what to expect.
A23: 3 | B23: Verification Email | C23: =394*2 -> 788 | D23: =C24/C23 -> 0.97208122 | E23: =1-D23 -> 0.027918782 | F23: =1-(C24/$C$22) -> 0.090261283 | G23: 0 | H23: 0 | I23: A message that says "Now confirm it's you", and some links to Gmail, Yahoo, Outlook to open the email and verify the email address | M23: [Open Gmail] & [Open Outlook] & [Open Yahoo] | N23: Open the email address | O23: Verify the email Address | P23: Yes | Q23: Yes | R23: Yes | S23: Good | T23: -- | U23: - | W23: [ACTION] If we run an a/b experiment by changing the copy from "Open Gmail | Open Outlook | Open Yahoo" to just "Gmail, Outlook, Yahoo", and the text to display above these CTAs will be "Get Verification Link on" [OUTCOME] we can evaluate if there is more click-throughs [Theory] because this new copy can remove some uncertainty and inform the user about the next step and what to expect.
A24: 4 | B24: Activate account in email | C24: =383*2 -> 766 | D24: =C25/C24 -> 0.96866841 | E24: =1-D24 -> 0.031331593 | F24: =1-(C25/$C$22) -> 0.11876485 | G24: 1 | H24: 0 | I24: A text and a CTA in the middle | M24: Activate account | N24: Click on the CTA to verify email | O24: Verify the email Address | P24: Yes | Q24: Yes | R24: Yes | S24: Good | T24: -- | U24: - | V24: No | W24: [ACTION] If we run an a/b experiment by changing the copy from "Activate account" to "Activate and create workspace", [OUTCOME] remove uncertainty again and let the user know what is the next step in his sign up process [Theory] because this new copy informs the user that the next step is creating the work space, and this will show that he is close enough to the end of the sign up process.
A25: 5 | B25: Submit personal info | C25: =371*2 -> 742 | D25: =C26/C25 -> 0.98921833 | E25: =1-D25 -> 0.010781671 | F25: =1-(C26/$C$22) -> 0.12826603 | G25: 5 | H25: 3 | I25: Two fields and a CTA at the buttom | M25: Continue | N25: Provide the name to create the workspace | O25: Creating the Workspace | P25: Yes | Q25: Yes | R25: Yes | S25: Good | T25: -- | U25: - | V25: No | W25: [ACTION] If we integrate this step with the followed one (creating workspace), [OUTCOME] we would be consistent in our messaging [Theory] because in the previous step, we made it clear to the user that in this step, he/she will create his/her workspace, and by integrating these two steps together, we will decease the step of the sign up process, and it won't be looking too long.
A26: 6 | B26: Name your workspace | C26: =367*2 -> 734 | D26: =C27/C26 -> 0.86376022 | E26: =1-D26 -> 0.13623978 | F26: =1-(C27/$C$22) -> 0.24703088 | G26: 3 | H26: 2 | I26: Two fields and a CTA at the buttom | M26: Continue | N26: Provide the name to create the workspace | O26: Creating the Workspace | P26: Yes | Q26: Yes | R26: Yes | S26: Good | T26: -- | U26: - | V26: No | W26: [ACTION] If we integrate this step with the previous one (Personal Info), [OUTCOME] we would be consistent in our messaging [Theory] because, we made it clear to the user, in the email, that in this step, he/she will create his/her workspace, and by integrating these two steps together, we will decease the step of the sign up process, and it won't be looking too long.
A27: 7 | B27: Invite Team | C27: =317*2 -> 634 | D27: =C28/C27 -> 0.96845426 | E27: =1-D27 -> 0.031545741 | F27: =1-(C28/$C$22) -> 0.27078385 | G27: 4 | H27: 3 | I27: 3 fields and 2 CTA at the buttom | M27: [Invite] & [Skip this] | N27: Email Addresses of colleagues the user wants to invite | O27: Invite colleagues | P27: Yes | Q27: Yes | R27: No, because the user can use the productboard without inviting the team | S27: Bad | T27: We can address it by adding a CTA in the previous step that informs the user if he want to continue by inviting a team or not. For example, we can add a pop-up window in the previous step, when the user clicks on Creating the workspace, and in this pop-up we can display this "invite colleagues and Skip this". This way, we can reduce the steps in the sign-up process and only those who want to invite their colleagues can continue the option of inviting colleagues. | U27: - | V27: No | W27: [ACTION] If we run an a/b experiment by changing the copy from "Invite Colleagues" to "Invite your team", [OUTCOME] we can test whether this CTA copy performs better or leave the first one [Theory] because this new copy can encourage the user to invite his/her colleagues, and it reflects that productboard is a place where you can make your team even stronger.
A28: 8 | B28: Password | C28: =307*2 -> 614 | D28: =C29/C28 -> 0.9218241 | E28: =1-D28 -> 0.078175896 | F28: =1-(C29/$C$22) -> 0.32779097
A29: 9 | B29: Survey | C29: =283*2 -> 566 | D29: =C30/C29 -> 1 | E29: =1-D29 -> 0 | F29: =1-(C30/$C$22) -> 0.32779097 | G29: 12 | H29: 0 | I29: One CTA at the buttom and a bunch of information to complete (e.g., Whether I'm in Marketing, Project Management, etc. Whether I want to use Product Board for myself or my team etc.) | M29: Show me how it works | N29: to tailor Productboard by providing some information including the size of the company and the role of the user in that company and whether he wants productboard for just himslef or the entire team etc. | O29: Tailor Productboard to user | P29: Yes | Q29: Yes | R29: Yes | S29: Good | T29: - | U29: - | V29: Yes | W29: [ACTION] If we run an a/b experiment by changing the copy from "Show me how it works" to "Give me a start guide", [OUTCOME] we can test whether this CTA copy performs better or leave the first one [Theory] because this copy is similar to what the user sees on the next step (Your quick start guide), this way, we can be more consistent in our messages.
A30: 10 | B30: User in-product | C30: =C29 -> 566
F31: Average | G31: Sum | H31: Sum
F32: =AVERAGE(F21:F29) -> 0.19685273 | G32: =SUM(G21:G29) -> 29 | H32: =SUM(H21:H29) -> 9

Sheet Tab 2 - Signup Experiments
A1: Measure drop-offs
A3: Scenario: The director of PM at Productboard has looked at your analysis of experiments in Tab 1 and wants to better understand how you will implement these experiments, your hypothesis on the impacts, how you will prioritize them, and how you will measure success. Not every experiment needs to be expanded on, so he asks to choose your top 5.
A4: Skill: You will implement the ICE framework to prioritize your experiments by giving them a growth score. Note: Further analysis and input from engineering and design does occur in the wild, which is removed from the scope of this exercise.
A5: Instructions: Complete the task with 1 row (experiment) at a time.
A6: 1. Use 5 experiments from Tab 1 - Column W and place them into Tab 2 - Column B.
A7: 2. In column D, elaborate on what is being tested
A8: 3. In column E, provide a qualitative and quantitative hypothesis of what will happen
A9: 4. In column F, describe the rationale of why you chose this experiment from any social proof, previous experience, or from any research.
A10: 5 In column G, provide a list of stakeholders who would need to be involved to release this experiment and why
A11: 6. In column H, document what more information is needed for you to execute on this experiment and document what assumptions you are making
A12: 7. In column I, provide a list of metrics that need to be measured in this experiment that would verify if the experiment failed or passed
A13: 8. In column J, provide a time-frame the experiment should be run for
... A16: Cells in Orange have been completed for you as an example. The formulas have been removed.
A17: A | B17: B | C17: C | D17: D | E17: E | F17: F | G17: G | H17: H | I17: I | J17: J | K17: K | L17: L | M17: M | N17: N | O17: O | P17: P
B18: Experiment Brief (from Tab 1) | C18: Which Step of Funnel (name and #) does this experiment impact? | D18: Describe what in the experiment is being tested? | E18: Hypothesis (What do you think will happen qualitatively and quantitatively?) | F18: Rationale (Why do you want to try this experiment?) | G18: Stakeholders (What other titles in the company needs to be involved? and why?) | H18: What more info do you need to decide this is an experiment you want to run? What assumptions are we making? | I18: What metrics should be measured? | J18: Length of time to run the experiment? | K18: What % of sign up users would you want to experiment with? | L18: What Friction is being removed? | M18: ICE - Impact? (be quantitative) | N18: ICE- Confidence | O18: ICE- Ease | P18: ICE - Growth Score
A19: 1 | B19: [ACTION] we can remove the top 50% of the step (role, team size, team use) [OUTCOME] so that we can inc the step completion rate from 92% [THEORY] because we would be decreasing 67% of the clicks on this step. | C19: 9 - survey | D19: We would remove the top portion of this step and only include the button. The screen would then only ask the user for bottom step that starts with "what are you hoping productboard will help you do?" The other steps we removed, we can look into tools like Clearbit that will help us collect the same data. | E19: We would remove 67% of the clicks and 4 fields from this step. At the moment the conversion on this step is 92%, but I think we can inc it to 95% as a result of this step. | F19: We are asking for too many fields at this step and the user is likely exhausted from going through 9 steps. We need to trim the sign up process to only the bare minimum items we need to get the user to the time-to-value as fast as possible. | G19: Sales team to determine how they use the survey data. Marketing team to determine how they use the survey data. Design team to create mockups of the new last step. Engineering team to unmap those fields and remove them from the back end, while keeping historical data. | H19: How sales uses this data? Is this data used for marketing engagement and onboarding? | I19: Higher step 9 conversions and higher total conversions of the funnel. | J19: 2-weeks | K19: 0.2 | L19: Collecting additional data that can be obtained for 3rd party resources. Asking for too much data | M19: 9 | N19: 9 | O19: 10 | P19: =average(M19:O19) -> 9.3333333
A20: 2 | B20: [ACTION] If we run an a/b experiment by changing the copy from "Sign up with work email" to "Get Verification Link", [OUTCOME] we can test whether this CTA copy performs better or leave the first one [Theory] because this new copy can remove some uncertainty and inform the user about the next step and what to expect. | C20: 2 - Free Trial Sign Up | D20: Change the CTA copy to Get verification link. So, we are changing only the text of the CTA and leave everything as it is. | E20: As we said earlier in Tab 1, by changing this text, we might remove some uncertainty about the next step, and guide the user through the journey. | F20: We are asking the user to sign up with work email, but it might be better to let the user about the next step by chnaging the copy. Also, the name work email may sound like a company email, while it's required to sign-up with company email, it can be personal email as well | G20: Design team to chnage the copy of the CTA | H20: -- | I20: higher Step 2 conversions and higher total conversions of the funnel | J20: 2-weeks | K20: 0.15 | L20: Uncertainty about the next step | M20: 8 | N20: 8 | O20: 10 | P20: =average(M20:O20) -> 8.6666667
A21: 3 | B21: [ACTION] If we run an a/b experiment by changing the copy from "Activate account" to "Activate and create workspace", [OUTCOME] remove uncertainty again and let the user know what is the next step in his sign up process [Theory] because this new copy informs the user that the next step is creating the work space, and this will show that he is close enough to the end of the sign up process. | C21: 4 - Activate Account in email | D21: Change the CTA copy to Activate and creat workspace. So, we are changing only the text of the CTA and leave everything as it is. | E21: the same as above, by changing the text, we would guide the user throuhg his/her journey and know what's the next step before even get to it. It is more like encouraging the user to continue on their journey by giving a hint about what the next step will be | F21: Same as above, in the link we have sent the user in his/her email address, we'he asked to activate account, and this may lead to some confusion, because the user might think that the sign-up process is limited to the account activation part, while it'll go beyond that step, that's why it'll be better to give a hint about what's required next. | G21: Design team to chnage the copy of the CTA | H21: -- | I21: higher Step 4 conversions and higher total conversions of the funnel | J21: 2-weeks | K21: 0.15 | L21: Uncertainty about the next step | M21: 7 | N21: 8 | O21: 10 | P21: =average(M21:O21) -> 8.3333333
A22: 4 | B22: [ACTION] If we integrate this step with the followed one (creating workspace), [OUTCOME] we would be consistent in our messaging [Theory] because in the previous step, we made it clear to the user that in this step, he/she will create his/her workspace, and by integrating these two steps together, we will decease the step of the sign up process, and it won't be looking too long. | C22: 5 - Submit Personal Info AND 6 - Name your work space | D22: We would integrate step 5 and 6 in one. So the step 5 will be about Submitting perosnal inof AND naming the workspace and then cancel the step 6 (because this step will be integrated with step five). | E22: By integrating step 6 with step 5, we would decrease the number of steps the user goes through by one step. | F22: In the previous step (4), we promised the user that he is going to create his workspace in his/her next step, so, it would normal to let the user create his/her workspace and not delayed to the next, because he was expecting to create it in this step. | G22: Engineering team to remove the step 6 and integrate it on step 6. Design team to create mockups of the new step 5&6 integrated | H22: -- | I22: higher new Step 5 (which will be step 5&6 integrated) conversions and higher total conversions of the funnel | J22: 3-weeks | K22: 0.2 | L22: inconsistency between step 4 and step 5 | M22: 9 | N22: 9 | O22: 8 | P22: =average(M22:O22) -> 8.6666667
A23: 5 | B23: [ACTION] If we run an a/b experiment by changing the copy from "Invite Colleagues" to "Invite your team", [OUTCOME] we can test whether this CTA copy performs better or leave the first one [Theory] because this new copy can encourage the user to invite his/her colleagues, and it reflects that productboard is a place where you can make your team even stronger. | C23: 7 - Invite Team | D23: Change the CTA copy to Invite your team. So, we are changing only the text of the CTA and leave everything as it is. | E23: By displaying this new copy rather than the old one, we would start building a good reputation by showing to users that they can invite their teams and make the product together | F23: The rational of this, is thgat the word colleague is vague, and it could refer to a colleague that he is not working with you on the same project or working for another departement. But, the word Team has more impact, because we work as a team for a specific project and an identified goals to acheive | G23: Design team to chnage the copy of the CTA | H23: -- | I23: higher Step 7 conversions and higher total conversions of the funnel | J23: 2-weeks | K23: 0.15 | L23: perception of the word colleague | M23: 7 | N23: 7 | O23: 10 | P23: =average(M23:O23) -> 8

Sheet Tab 3 - Activation Hypothesis
A1: Activation Hypothesis
A2: Scenario: After doing such an amazing job for Productboard with signup, you have now been brought onto a project at Slack. Slack's revenues have been decreasing by 5% and leadership believes it's an activation problem due to not understanding what we should be guiding our users to-do in our product when the user is signing up.
A3: You've been tasked to define a more robust activation funnel to achieve shorter time-to-value, product usage, and revenue. You will (1) be able to tell Marketing and the Growth PM focusing on acquisition which segment of our users are performing these actions best and (2) determine what moments and metrics we should be driving our users towards. NOTE: The rest of the project relates entirely to Slack or a realtime messaging service like Slack.
A4: You will (1) be able to tell Marketing and Growth PM focusing on acquisition which segment of our users are performing these actions best (2) determine what moments and metrics we should be driving our users towards. NOTE: The rest of the project relates entirely to Slack or a realtime messaging service like Slack.
A5: Skill: Before doing any analysis, you want to start off with a hypothesis. Before you quantitatively measure the activation funnel, define your understanding of the product by creating a hypothesis of what the Habit, Aha, and Setup moments are for Slack.
A6: =HYPERLINK("https://slack.com/get-started#/ ","Instructions: Signup for Slack at https://slack.com/get-started#/") -> Instructions: Signup for Slack at https://slack.com/get-started#/
A7: After signing up for Slack, determine what actions in the product and marketing messages the user is driven to. From the actions you are driven to as a new user, determine which actions are leading you to an aha moment to see value of the product or setup moment that are leading you to properly setup your account.
A8: An example of an Setup Moment is that they market themselves as a replacement of Email on their marketing website, so when you start using the product, they likely get you to take action via Slack what you would normally do via email.
A9: An example of Aha Moment is that they get you to engage with the Slackbot or your college, so you can engaging with others, weather that is a human, bots, or other 3rd party services to see value of the tool.
A10: Create a hypothesis of what the habit, aha, and setup moments should be for Slack. (Note: this is only for data-dump and for critical thinking.)
A11: The answers here are hypothesis based on your experience of starting to use Slack. In addition to creating a new account on Slack, browse through their features page to spark ideas of potential aha moments: https://slack.com/features.
A12: 1. List 4 in-product moments you think that if done often would lead a Slack user to build a habit in Row 18-21
A13: 2. List 4 aha moments in-product that you think if reached, seen, or experienced would get a user to understand the value provided by Slack in Row 15-19
A14: 2. List 4 aha moments in-product that you think if reached, seen, or experienced would get a user to understand the value provided by Slack in Row 31-34.
A15: A | B15: B
A16: Cells in Orange have been completed for you as an example. The formulas have been removed.
A17: Moment that lead to Habit:
A18: 1 | B18: Only use Slack, not email, for internal messages
A19: 2 | B19: checking tagged messages in a group chat
A20: 3 | B20: message anyone from the team without the need for an email address
A21: 4 | B21: Learn about your teammates (from other departements) by consulting their profiles and even getting their phone number when possible
A22: 5 | B22: Sign in and stay active in multiple workspaces
A23: Moment that lead to Aha:
A24: 1 | B24: Getting notifications from team on a group channel
A25: 2 | B25: Stay connected and up to date by installing the phone app as well as the website
A26: 3 | B26: Find other general workspaces, not only those related to your company, and engage with the community that you like
A27: 4 | B27: Use direct channel to communicate with a cpecific team member
A28: 5 | B28: Getting access to documents and files that have been saved before
A29: Moment that lead to Setup:
A30: 1 | B30: Engage in a frequency faster than email while being mobile
A31: 2 | B31: Create your own workspace or even a new channel within a workspace
A32: 3 | B32: Integrate a third party app
A33: 4 | B33: invite a team member
A34: 5 | B34: Set up the profile by adding more information, like phone number, etc.

Sheet Tab 4 - Habit Moment and Metric
A1: Habit Moment and Metric Analysis
A2: Scenario: The VP of Product took your team's hypothesis and narrowed down them down to 3 moments and 3 metrics each fro Habit, Aha, and Setup analysis. The ones provided could include your hypothesis from Tab 3, but if they do not, that does not mean yours hypothesis is not valid. With the VP's experience, he is simply able to narrow down the list for us.
A3: You need to conduct an analysis on what habit moments and metrics drive users to long-term activation. Remember: Long-term activation would be defined by the metric with the highest % overlap curve.
A4: The habit, aha, and setup moments will be shared across next three tabs one for each moment. In this tab, you will analyze just habit moments/metrics and determine whether each of these 3 habit moments affect activation. This is important to know because then we can tailor our product to include the features that allow our users to achieve activation faster. 3 Habit Moments and 3 Habit Metrics are pre-selected for you along with users who completed actions and retained for each of the 3 moments.
A5: Habit 1 analysis is on row 18-20, habit 2 analysis is on row 30-36, and habit 3 analysis is on row 42-48.
A6: Skills: (1) calculate % overlap to measure the relationship of % overlap to habit metric (2) create line charts to visualize the relationship of the metric (3) analyze which are the primary habit moments and metric that lead to long-term activation.
A7: Instructions: Place any notes, thoughts, comments in the "Observations (Personal Notes)" box in column M -O for yourself as you may want them in the future
A8: 1. Calculate the % overlap for each moment in Column F,
A9: 2. Create a line-graph for each moment in Column H-K to visualize the % Overlap from Column F vs Habit Metric from column A,
A10: 3. Analyze the data for each moment to determine if based on your analysis, this moment leads to long-term activation or not, and share your reasoning in Column Q - S
A11: 4. Once Steps 1 - 3 are completed, determine which of the 3 options would the Primary Habit Moment and Metric and explain why in the 2 boxes on the bottom right of this Tab in Row 51.
A12: Cells in Orange have been completed for you as an example. The formulas have been removed.
A14: Habit Moment 1: look for a communication tool outside of email to engage with teammates
A15: Habit Metric 1: # of Team Slack Messages Sent in 7-days | M15: Observations (Personal Notes): Sending 20000 messages a week has the largest %overlap with 58%. Therefore this is the ideal optimum is to send 20000 to get our users to create a habit. | Q15: Does doing this Habit Metric affect activation? If yes, what is the ideal metric? | S15: Yes. The ideal metric is 20000 messages a week
A16: # of | B16: User
A17: Messages Sent | B17: Action Completed | C17: Retained + Action NOT completed | D17: Retained + Action completed | E17: Total Users | F17: % Overlap
A18: 100 | B18: =997-200 -> 797 | C18: =139+0 -> 139 | D18: =358 -> 358 | E18: =B18+C18 -> 936 | F18: =D18/E18 -> 0.38247863
A19: 500 | B19: =620-200 -> 420 | C19: 146 | D19: 282 | E19: =B19+C19 -> 566 | F19: =D19/E19 -> 0.49823322 | Q19: Why? | R19: Because as uers send messages over and over again outside of email lto engage with teammates, they became attached to it, beasue they have the possibility to use email for this prupose, but they prefer to use slack instead and this creates a habit for them for sure.
A20: 1000 | B20: =565-200 -> 365 | C20: 158 | D20: 249 | E20: =B20+C20 -> 523 | F20: =D20/E20 -> 0.47609943
A21: 2000 | B21: =432-200 -> 232 | C21: 171 | D21: 222 | E21: =B21+C21 -> 403 | F21: =D21/E21 -> 0.55086849
A22: 5000 | B22: 185 | C22: 190 | D22: 210 | E22: =B22+C22 -> 375 | F22: =D22/E22 -> 0.56
A23: 10000 | B23: 150 | C23: 200 | D23: 200 | E23: =B23+C23 -> 350 | F23: =D23/E23 -> 0.57142857
A24: 20000 | B24: 120 | C24: 210 | D24: 190 | E24: =B24+C24 -> 330 | F24: =D24/E24 -> 0.57575758
A26: Habit Moment 2: Only use Slack for internal messages, not email
A27: Habit Metric 2: # of sessions (log-ins) per day | M27: Observations (Personal Notes): Based on the results of %overlap of this provided metric, we see that (3+) & (4+) & (6+) log-ins share the same %overlap, which is 45%. and this make difficult to decide what's the ideal optimum that leads user to create a habit. | Q27: Does doing this Habit Metric affect activation? If yes, what is the ideal metric? | S27: NO
A28: Session | B28: User
A29: (log-ins) | B29: Action Completed | C29: Retained + Action NOT completed | D29: Retained + Action completed | E29: Total Users | F29: % Overlap
A30: 1+ | B30: =954+150 -> 1104 | C30: =192 -> 192 | D30: =303+150 -> 453 | E30: =B30+C30 -> 1296 | F30: =D30/E30 -> 0.34953704
A31: 2+ | B31: =540+150 -> 690 | C31: =223+150 -> 373 | D31: =277+150 -> 427 | E31: =B31+C31 -> 1063 | F31: =D31/E31 -> 0.40169332 | Q31: Why? | R31: Because the largest %overlap is 45% and it's shared between three log-ins (3+, 4+, 6+), which make it hard to choose which # of log-ins that get our users to create a habit. Therefore, we can't decide based on the results of this habit metric
A32: 3+ | B32: =402+150 -> 552 | C32: =238+120 -> 358 | D32: =262+150 -> 412 | E32: =B32+C32 -> 910 | F32: =D32/E32 -> 0.45274725
A33: 4+ | B33: =310+150 -> 460 | C33: =272+100 -> 372 | D33: =228+150 -> 378 | E33: =B33+C33 -> 832 | F33: =D33/E33 -> 0.45432692
A34: 5+ | B34: =278+150 -> 428 | C34: =291+100 -> 391 | D34: =209+150 -> 359 | E34: =B34+C34 -> 819 | F34: =D34/E34 -> 0.43833944
A35: 6+ | B35: =202+150 -> 352 | C35: =334 -> 334 | D35: =156+150 -> 306 | E35: =B35+C35 -> 686 | F35: =D35/E35 -> 0.44606414
A36: 7+ | B36: =160+150 -> 310 | C36: =363 -> 363 | D36: =137+150 -> 287 | E36: =B36+C36 -> 673 | F36: =D36/E36 -> 0.42644874
A38: Habit Moment 3: Checking a notification when something is addressed to me
A39: Habit Metric 3: # of messages they were linked to (with an @) that brought them back to Slack | M39: Observations (Personal Notes): Checking a (1+) message has the largest %overlap, and this make it, theoritically, the ideal optimum that leads our users to create a habit. | Q39: Does doing this Habit Metric affect activation? If yes, what is the ideal metric? | S39: NO
A40: # of | B40: User
A41: Messages | B41: Action Completed | C41: Retained + Action NOT completed | D41: Retained + Action completed | E41: Total Users | F41: % Overlap
A42: 1+ | B42: =997-600 -> 397 | C42: 139 | D42: 250 | E42: =B42+C42 -> 536 | F42: =D42/E42 -> 0.46641791
A43: 2+ | B43: =620-350 -> 270 | C43: 146 | D43: 190 | E43: =B43+C43 -> 416 | F43: =D43/E43 -> 0.45673077 | Q43: Why? | R43: Because, when someone addresses us on a messaging app or platform, we automatically respond, that's a human nature and behaviour. Even when someone addresses us on a platform that we are not really attached to it, we respond without any further thinking about how the app is designed or what are its amazing features or something like that.
...

Sheet Tab 5 - Aha Moment and Metric A
A1: Aha Moment and Metric Analysis
A2: Scenario: The VP of Product took your team's hypothesies and narrowed down them down to 3 moments and 3 metrics each fro Habit, Aha, and Setup analysis. The ones provided could include your hypothesis from Tab 3, but if they do not, that does not mean yours hypothesis is not valid. With the VP's experience, he is simply able to narrow down the list for us.
A3: You need to conduct an analysis on what habit moments and metrics drive users to long-term activation. Remember: Long-term activation would be defined by the metric with the highest % overlap curve.
A4: The habit, aha, and setup moments will be shared across next three tabs one for each moment. In this tab, you will analyze just Aha moments/metrics and determine whether each of these 3 habit moments affect activation. This is important to know because then we can tailor our product to include the features that allow our users to achieve activation faster. 3 Aha Moments and 3 Aha Metrics are pre-selected for you along with users who completed actions and retained for each of the 3 moments.
A5: Skill: From these tasks, you can apply your knowledge on how to (1) calculate % overlap to measure the relationship of % overlap to Aha metric, (2) create line charts to visualize the relationship of the metric and (3) analyze which are the primary Aha moments and metric that lead to long-term activation.
A6: Instructions: Place any notes, thoughts, comments in the "Observations (Personal Notes)" box in column M - O for yourself to view in the future.
A7: 1. Calculate the % overlap for each moment in Column F,
A8: 2. Create a line-graph for each moment in Column H-K to visualize the % Overlap from Column F vs aha Metric from column A,
A9: 3. Analyze the data for each moment to determine if based on your analysis, this moment leads to long-term activation or not, and share your reasoning in Column Q - S
A10: 4. Once Steps 1 - 3 are completed, determine which of the 3 options would the Primary aha Moment and Metric and explain why in the 2 boxes on the bottom right of this Tab in Row 50.
A11: Cells in Orange have been completed for you as an example. The formulas have been removed.
A13: Aha Moment 1: Engaging with a message in a group channel
A14: Aha Metric 1: Sending 1st message in a group channel within X days | M14: Observations (Personal Notes): Sending the 1st message in a group channel within the (1+) days has the largest %overlap with 83%. taking 7+ days to send the first message has the lowest %overlap, which is only 32%. We might say that the %overlap has a negative relationship with days the users take to send their first message. | Q14: Does doing this Aha Metric affect activation? If yes, what is the ideal metric? | S14: Yes. The ideal metric is to send the first message within the (1+) days
A15: # of | B15: User
A16: Days Taken | B16: Action Completed | C16: Retained + Action NOT completed | D16: Retained + Action completed | E16: Total Users | F16: % Overlap
A17: 1+ | B17: =954-750 -> 204 | C17: =192+150 -> 342 | D17: =303+150 -> 453 | E17: =B17+C17 -> 546 | F17: =D17/E17 -> 0.82967033
A18: 2+ | B18: =540-370 -> 170 | C18: 360 | D18: =277+150 -> 427 | E18: =B18+C18 -> 530 | F18: =D18/E18 -> 0.80566038 | Q18: Why? | R18: Because in the previous sheet (habit Moment), we considered that looking for a communication tool outside of email to engage with teammates is a habit moment, therefore this Aha Moment (engage with a message in a group channel) will lead that user to create a habit. So, our Aha and Habit moment are related and the Aha will lead to creating a Habit.
A19: 3+ | B19: =402-250 -> 152 | C19: 370 | D19: =262+150 -> 412 | E19: =B19+C19 -> 522 | F19: =D19/E19 -> 0.78927203
A20: 4+ | B20: =310-200 -> 110 | C20: 380 | D20: =228+150 -> 378 | E20: =B20+C20 -> 490 | F20: =D20/E20 -> 0.77142857
A21: 5+ | B21: 90 | C21: 520 | D21: =209+150 -> 359 | E21: =B21+C21 -> 610 | F21: =D21/E21 -> 0.58852459
A22: 6+ | B22: 65 | C22: 650 | D22: =156+150 -> 306 | E22: =B22+C22 -> 715 | F22: =D22/E22 -> 0.42797203
A23: 7+ | B23: 30 | C23: 874 | D23: =137+150 -> 287 | E23: =B23+C23 -> 904 | F23: =D23/E23 -> 0.31747788
A25: Aha Moment 2: Messaging with a team member on a direct channel
A26: Aha Metric 2: sends 1st direct message within X days | M26: Observations (Personal Notes): Sending the 1st direct message within the (1+) days has the largest %overlap with 61%. taking 7+ days to send the first direct message has the lowest %overlap, which is only 23% only. We might say that the %overlap has a negative relationship with days the users take to send their first direct message. | Q26: Does doing this Aha Metric affect activation? If yes, what is the ideal metric? | S26: Yes. The ideal metric is to send the first direct message within the (1+) days
A27: # of | B27: User
A28: Days Taken | B28: Action Completed | C28: Retained + Action NOT completed | D28: Retained + Action completed | E28: Total Users | F28: % Overlap
A29: 1+ | B29: =954+150 -> 1104 | C29: 200 | D29: 800 | E29: =B29+C29 -> 1304 | F29: =D29/E29 -> 0.61349693
A30: 2+ | B30: =540+150 -> 690 | C30: =223+150 -> 373 | D30: =277+150+200 -> 627 | E30: =B30+C30 -> 1063 | F30: =D30/E30 -> 0.58984008 | Q30: Why? | R30: Same as above Sending a direct message to a teammate would increase the chance to reach Aha, because some users would think that slack is only about a group messaging and not sending direct messages. So, experiencing this feature will lead users to Aha, and this will be consistent with what we consider as a Habit Moement (sheet 4). Making it easier for users to send a direct messages to their teammates will decrease their needs to go to email to do so, because sending a direct message to teammate via Slack is faster and users won't have to go back and forth between apps (Slack and Email); they will be more productive and focus.
A31: 3+ | B31: =402+150 -> 552 | C31: =238+150 -> 388 | D31: =262+150+120 -> 532 | E31: =B31+C31 -> 940 | F31: =D31/E31 -> 0.56595745
A32: 4+ | B32: =310+150 -> 460 | C32: =272+150-50 -> 372 | D32: =228+150+80 -> 458 | E32: =B32+C32 -> 832 | F32: =D32/E32 -> 0.55048077
A33: 5+ | B33: =278+150 -> 428 | C33: =291+150 -> 441 | D33: =209+150 -> 359 | E33: =B33+C33 -> 869 | F33: =D33/E33 -> 0.41311853
A34: 6+ | B34: =202+150 -> 352 | C34: =334+150 -> 484 | D34: =156+150 -> 306 | E34: =B34+C34 -> 836 | F34: =D34/E34 -> 0.36602871
A35: 7+ | B35: =160+150 -> 310 | C35: =363+150 -> 513 | D35: =137+150-100 -> 187 | E35: =B35+C35 -> 823 | F35: =D35/E35 -> 0.2272175
A37: Aha Moment 3: Searching for old documents, links, and convos
A38: Aha Metric 3: 1st search for a file or message within X days | M38: Observations (Personal Notes): make the first search for a file or message within the (3+) days has the largest %overlap with 61%. taking 7+ days to search for first file or message has the lowest %overlap, which is only 35% only. | Q38: Does doing this Aha Metric affect activation? If yes, what is the ideal metric? | S38: No
A39: # of | B39: User
A40: Days Taken | B40: Action Completed | C40: Retained + Action NOT completed | D40: Retained + Action completed | E40: Total Users | F40: % Overlap
A41: 1+ | B41: =954+150 -> 1104 | C41: =192+150 -> 342 | D41: =303+300 -> 603 | E41: =B41+C41 -> 1446 | F41: =D41/E41 -> 0.41701245
A42: 2+ | B42: =540+150 -> 690 | C42: =223+150 -> 373 | D42: =277+150 -> 427 | E42: =B42+C42 -> 1063 | F42: =D42/E42 -> 0.40169332 | Q42: Why? | R42: Because every platform now is built with the function of searching for old document and messages, so this might not get our users to reach Aha, because they will expecting this feature to be integrated in the product.
A43: 3+ | B43: =402+150 -> 552 | C43: =238+150 -> 388 | D43: =262+150 -> 412 | E43: =B43+C43 -> 940 | F43: =D43/E43 -> 0.43829787
...

Sheet Tab 6 - Setup Moment and Metric
A1: Setup Moment and Metric Analysis
A2: Scenario: The VP of Product took your team's hypothesies and narrowed down them down to 3 moments and 3 metrics each fro Habit, Aha, and Setup analysis. The ones provided could include your hypothesis from Tab 3, but if they do not, that does not mean yours hypothesis is not valid. With the VP's experience, he is simply able to narrow down the list for us.
A3: You need to conduct an analysis on what habit moments and metrics drive users to long-term activation. Remember: Long-term activation would be defined by the metric with the highest % overlap curve.
A4: The habit, Setup, and setup moments will be shared across next three tabs one for each moment. In this tab, you will analyze just Setup moments/metrics and determine whether each of these 3 habit moments affect activation. This is important to know because then we can tailor our product to include the features that allow our users to achieve activation faster. 3 Setup Moments and 3 Setup Metrics are pre-selected for you along with users who completed actions and retained for each of the 3 moments.
A5: Skill: From these tasks, you can apply your knowledge on how to (1) calculate % overlap to measure the relationship of % overlap to setup metric (2) create line charts to visualize the relationship of the metric (3) analyze which are the primary setup moments and metric that lead to long-term activation.
A6: Instructions: Place any notes, thoughts, comments in the "Observations (Personal Notes)" box in column M - O for yourself to view in the future.
A7: 1. Calculate the % overlap for each moment in Column F,
A8: 2. Create a line-graph for each moment in Column H-K to visualize the % Overlap from Column F vs setup Metric from column A,
A9: 3. Analyze the data for each moment to determine if based on your analysis, this moment leads to long-term activation or not, and share your reasoning in Column Q - S
A10: 4. Once Steps 1 - 3 are completed, determine which of the 3 options would the Primary setup Moment and Metric and explain why in the 2 boxes on the bottom right of this Tab in Row 50.
A11: Cells in Orange have been completed for you as an example. The formulas have been removed.
A12: Setup Moment 1: Configure settings and profile
A13: Setup Metric 1: Setting up profile pic within X days | M13: Observations (Personal Notes): Setting up a profile pic within the (1+) days has the largest %overlap (40%). taking 7+ days to set up a profile pic has the lowest %overlap, which is only 31%. | Q13: Does doing this Setup Metric affect activation? If yes, what is the ideal metric? | S13: Yes. The ideal metric is to set up a profile pic within the (1+) day
A14: # of | B14: User
A15: Days Taken | B15: Action Completed | C15: Retained + Action NOT completed | D15: Retained + Action completed | E15: Total Users | F15: % Overlap
A16: 1+ | B16: =954+150+100 -> 1204 | C16: =192+150 -> 342 | D16: =303+300 -> 603 | E16: =B16+C16 -> 1546 | F16: =D16/E16 -> 0.39003881
A17: 2+ | B17: =540+150+100 -> 790 | C17: =223+150 -> 373 | D17: =277+150 -> 427 | E17: =B17+C17 -> 1163 | F17: =D17/E17 -> 0.36715391 | Q17: Why? | R17: Because teammates need to know who are they talking to, and picture is good way to do so. Because if they're working for a large company, they might not see each other but they can contact each other, if someone need something from someone else working on a different departement within that same company, so setting up a profile pic is a good way to represent yourself to your colleagues working for the same company.
A18: 3+ | B18: =402+150+100 -> 652 | C18: =238+150 -> 388 | D18: =262+150 -> 412 | E18: =B18+C18 -> 1040 | F18: =D18/E18 -> 0.39615385
A19: 4+ | B19: =310+150+100 -> 560 | C19: =272+150 -> 422 | D19: =228+150 -> 378 | E19: =B19+C19 -> 982 | F19: =D19/E19 -> 0.38492872
A20: 5+ | B20: =278+150+100 -> 528 | C20: =291+150 -> 441 | D20: =209+150 -> 359 | E20: =B20+C20 -> 969 | F20: =D20/E20 -> 0.37048504
A21: 6+ | B21: =202+150+100 -> 452 | C21: =334+150 -> 484 | D21: =156+150 -> 306 | E21: =B21+C21 -> 936 | F21: =D21/E21 -> 0.32692308
A22: 7+ | B22: =160+150+100 -> 410 | C22: =363+150 -> 513 | D22: =137+150 -> 287 | E22: =B22+C22 -> 923 | F22: =D22/E22 -> 0.31094258
A24: Setup Moment 2: Integrate to a 3rd party Slack App
A25: Setup Metric 2: Integrate to a 3rd party app within 7-days | M25: Observations (Personal Notes): Integrate to a 3rd party app within the (1+) days has the largest %overlap (57%). taking 7+ to integrate to a 3rd party app has the lowest %overlap, which is only 47%. | Q25: Does doing this Setup Metric affect activation? If yes, what is the ideal metric? | S25: Yes. The ideal metric is to integrate a 3rd party app within the (1+) day
A26: # of | B26: User
A27: Days Taken | B27: Action Completed | C27: Retained + Action NOT completed | D27: Retained + Action completed | E27: Total Users | F27: % Overlap
A28: 1+ | B28: =954+150+100 -> 1204 | C28: 200 | D28: 800 | E28: =B28+C28 -> 1404 | F28: =D28/E28 -> 0.56980057
A29: 2+ | B29: =540+150+100 -> 790 | C29: =223+150 -> 373 | D29: =277+150+200 -> 627 | E29: =B29+C29 -> 1163 | F29: =D29/E29 -> 0.53912296 | Q29: Why? | R29: Because integrating 3rd party app will increase the chances of reaching Aha moment, as users see the value and the features that Slack provides in order to make their work efficient, and not only about chatting and sending messages.
A30: 3+ | B30: 620 | C30: =238+150 -> 388 | D30: =262+150+120 -> 532 | E30: =B30+C30 -> 1008 | F30: =D30/E30 -> 0.52777778
A31: 4+ | B31: 510 | C31: =272+150-50 -> 372 | D31: =228+150+80 -> 458 | E31: =B31+C31 -> 882 | F31: =D31/E31 -> 0.51927438
A32: 5+ | B32: 272 | C32: =291+150 -> 441 | D32: =209+150 -> 359 | E32: =B32+C32 -> 713 | F32: =D32/E32 -> 0.50350631
A33: 6+ | B33: 135 | C33: =334+150 -> 484 | D33: =156+150 -> 306 | E33: =B33+C33 -> 619 | F33: =D33/E33 -> 0.49434572
A34: 7+ | B34: 50 | C34: 590 | D34: 300 | E34: =B34+C34 -> 640 | F34: =D34/E34 -> 0.46875
A36: Setup Moment 3: Invite a team mate and had a back-and-forth direct convo
A37: Setup Metric 3: # of users invited within 7-days | M37: Observations (Personal Notes): Inviting a teammate within the (1+) days has the largest %overlap (40%). taking 7+ to invit a teammate has the lowest %overlap, which is only 29%. | Q37: Does doing this Setup Metric affect activation? If yes, what is the ideal metric? | S37: Yes. The ideal metric is to invite a teammate within the (1+) day
A38: # of | B38: User
A39: Users Invited | B39: Action Completed | C39: Retained + Action NOT completed | D39: Retained + Action completed | E39: Total Users | F39: % Overlap
A40: 1+ | B40: =954-750+100 -> 304 | C40: =192+150 -> 342 | D40: =303+150 -> 453 | E40: =B40+C40 -> 646 | F40: =D40/E40 -> 0.70123839
A41: 2+ | B41: =540-370+100 -> 270 | C41: 360 | D41: =277+150 -> 427 | E41: =B41+C41 -> 630 | F41: =D41/E41 -> 0.67777778 | Q41: Why? | R41: this metric is related to what we have considered as Aha and Habit moments. If we gave users the ability to invite other users to the workspace or channel, this will decrease the need for contacting them via Email, because by inviting them to the workspace for example, users will be able to contact them in a group channel, or even send them direct messages without the need to go and open Email and send them a message, which will then help in acheving a Habit Moment later on.
A42: 3+ | B42: =402-250+100 -> 252 | C42: 370 | D42: =262+150 -> 412 | E42: =B42+C42 -> 622 | F42: =D42/E42 -> 0.66237942
...

Sheet Tab 7 - Activation Funnel
A1: Activation Funnel | D1: Suggested Experiments from Tab 3
A2: Scenario: You have been brought onto a project at Slack to help define the activation funnel. | D2: ='Tab 3 - Activation Hypothesis'!A17 -> Moment that lead to Habit:
A3: On this tab, you will be putting all the analysis you've done in previous 3 tabs together. From the 3 previous tabs, you should have identified the primary habit, aha, and signup moment that most influenced activation. | D3: =CONCATENATE('Tab 3 - Activation Hypothesis'!A18," ",'Tab 3 - Activation Hypothesis'!B18) -> 1 Only use Slack, not email, for internal messages
D4: =CONCATENATE('Tab 3 - Activation Hypothesis'!A19," ",'Tab 3 - Activation Hypothesis'!B19) -> 2 checking tagged messages in a group chat
A5: Skill: You have determined that many moments and metrics can lead users to activate, but there are only a few Primary moments and metrics that we should drive users towards as they lead to long-term activation. | D5: =CONCATENATE('Tab 3 - Activation Hypothesis'!A20," ",'Tab 3 - Activation Hypothesis'!B20) -> 3 message anyone from the team without the need for an email address
A6: Instructions: Compare your hypothesis from Tab 3- Activation Hyopthesis against the post-analysis activation funnel in Tab 7. Please add your thoughts Column C. | D6: =CONCATENATE('Tab 3 - Activation Hypothesis'!A21," ",'Tab 3 - Activation Hypothesis'!B21) -> 4 Learn about your teammates (from other departements) by consulting their profiles and even getting their phone number when possible
A7: 1. Your Habit moments and metrics (They should appear here from the relevant tabs, if they do not, please copy them here) for your to reflect on are in A11 and B11 | D7: =CONCATENATE('Tab 3 - Activation Hypothesis'!A22," ",'Tab 3 - Activation Hypothesis'!B22) -> 5 Sign in and stay active in multiple workspaces
A8: 2. Your Aha moments and metrics (They should appear here from the relevant tabs, if they do not, please copy them here) for your to reflect on are in A11 and B12 | D8: ='Tab 3 - Activation Hypothesis'!A23 -> Moment that lead to Aha:
A9: 3. Your Setup moments and metrics (They should appear here from the relevant tabs, if they do not, please copy them here) for your to reflect on are in A11 and B13 | D9: =CONCATENATE('Tab 3 - Activation Hypothesis'!A24," ",'Tab 3 - Activation Hypothesis'!B24) -> 1 Getting notifications from team on a group channel
A10: Cells in orange have been done for you. | D10: =CONCATENATE('Tab 3 - Activation Hypothesis'!A25," ",'Tab 3 - Activation Hypothesis'!B25) -> 2 Stay connected and up to date by installing the phone app as well as the website
A11: Moment that lead to Habit: | B11: Metrics that lead to Habit: | C11: Observations/Reflections on Hypothesis | D11: =CONCATENATE('Tab 3 - Activation Hypothesis'!A26," ",'Tab 3 - Activation Hypothesis'!B26) -> 3 Find other general workspaces, not only those related to your company, and engage with the community that you like
A12: ='Tab 4 - Habit Moment and Metric'!R51 -> look for a communication tool outside of email to engage with teammates | B12: ='Tab 4 - Habit Moment and Metric'!S51 -> # of Team Slack Messages Sent in 7-days (sending 20000 messages) | C12: No further thoughts | D12: =CONCATENATE('Tab 3 - Activation Hypothesis'!A27," ",'Tab 3 - Activation Hypothesis'!B27) -> 4 Use direct channel to communicate with a cpecific team member
A13: Moment that lead to Aha: | B13: Metrics that lead to Aha: | D13: =CONCATENATE('Tab 3 - Activation Hypothesis'!A28," ",'Tab 3 - Activation Hypothesis'!B28) -> 5 Getting access to documents and files that have been saved before
A14: ='Tab 5 - Aha Moment and Metric A'!R50 -> Messaging with a team member on a direct channel | B14: ='Tab 5 - Aha Moment and Metric A'!S50 -> sends 1st direct message within X days (Send the 1st direct message within the (1+) days) | C14: No further thoughts | D14: ='Tab 3 - Activation Hypothesis'!A29 -> Moment that lead to Setup:
A15: Moments that lead to Signup: | B15: Metrics that lead to Signup: | D15: =CONCATENATE('Tab 3 - Activation Hypothesis'!A30," ",'Tab 3 - Activation Hypothesis'!B30) -> 1 Engage in a frequency faster than email while being mobile
A16: ='Tab 6 - Setup Moment and Metric'!R49 -> Setup Moment 3: Invite a team mate and had a back-and-forth direct convo | B16: ='Tab 6 - Setup Moment and Metric'!S49 -> Setup Metric 3: # of users invited within 7-days (Inviting a teammate within the (1+) days) | C16: No further thoughts | D16: =CONCATENATE('Tab 3 - Activation Hypothesis'!A31," ",'Tab 3 - Activation Hypothesis'!B31) -> 2 Create your own workspace or even a new channel within a workspace
D17: =CONCATENATE('Tab 3 - Activation Hypothesis'!A32," ",'Tab 3 - Activation Hypothesis'!B32) -> 3 Integrate a third party app
D18: =CONCATENATE('Tab 3 - Activation Hypothesis'!A33," ",'Tab 3 - Activation Hypothesis'!B33) -> 4 invite a team member
D19: =CONCATENATE('Tab 3 - Activation Hypothesis'!A34," ",'Tab 3 - Activation Hypothesis'!B34) -> 5 Set up the profile by adding more information, like phone number, etc.

Sheet Tab 8 - Segment Analysis
A1: Segment Analysis
A2: Scenario: Now that you have determined one of Slack's Habit, Aha, and Setup moments, you have been asked by the VP of Product to segment our users through the activation funnel. He requests you share with marketing any findings on what users are performing well, not well, and what areas can be improved on.
A3: The findings will help marketing team focus on Ideal Customer Profiles (ICPs), so they know where to invest for Acquisition. The activation funnel has already been applied to these segments and your goal is to see analyze delta between the funnel and how many users make it through the funnel.
A4: Remember: The delta is the percentage of users that make it from one stage of the funnel to the next to ultimately tell us what percent of our acquired users go through all stages of funnel to achieve activation.
A5: Once your conduct this analysis, you can then create experiments on how to convert more users through each step in the Setup, Aha, and Habit moments. The goal for Slack is to get more users through the funnel so we have more users and a higer % of users that become activated.
A6: Skill: Analyze how different segments flow through the activation funnel by determining the # and % of users activated per segment.
A7: Instructions: Conduct each segment analysis in order: Industry (Row 8 - 28) Company Size (Row 30 -50) Account Size (Row 52 - 71) Source (Row 73 - 90).
A8: Place any notes, thoughts, comments in the "Observations (Personal Notes)" box for yourself to view in the future - these will not be graded.
A9: In your text-based analysis, your goal is to increase the total average % you calculate in row 31, 53, 74, and 93 across each segment. To determine what is a good threshold of % of users activated that is good enough vs.needs more support, compare the % users activated for each segmen to the average for that segment.
A10: 1. Calculate the Delta (Setup to Aha) ratio in Column D
A11: 2. Calculate Delta (Aha to Habit) ratio in Column F,
A12: 3. Calculate # of users activated in Column H,
... A15: Cells colored in Blue have ben completed as examples for you. The formulas have been removed.
A16: Segment Analysis by Industry for June 2019 | K16: Observations (Personal Notes)
A17: Industry | B17: New Users Acquired | C17: Activation Funnel | H17: # of Users activated | I17: % of Users Activated
A18: Total | B18: =sum(B19:B26) -> 920.6 | C18: Setup Moment | D18: Delta (Setup to Aha) | E18: Aha Moment | F18: Delta (Aha to Habit) | G18: Habit Moment
A19: Technology | B19: =310*0.9 -> 279 | C19: 0.85 | D19: =E19/C19 -> 0.91764706 | E19: 0.78 | F19: 0.87 | G19: 0.68 | H19: 126 | I19: =H19/B19 -> 0.4516129
A20: Retail | B20: =206*0.8 -> 164.8 | C20: 0.76 | D20: =E20/C20 -> 0.90789474 | E20: 0.69 | F20: =G20/E20 -> 0.91304348 | G20: 0.63 | H20: =B20*C20*E20*G20 -> 54.445306 | I20: =H20/B20 -> 0.330372
A21: Healthcare | B21: =172*0.8 -> 137.6 | C21: 0.8 | D21: =E21/C21 -> 0.95 | E21: 0.76 | F21: =G21/E21 -> 0.92105263 | G21: 0.7 | H21: =B21*C21*E21*G21 -> 58.56256 | I21: =H21/B21 -> 0.4256
A22: Financial Services | B22: =138*0.8 -> 110.4 | C22: 0.76 | D22: =E22/C22 -> 0.90789474 | E22: 0.69 | F22: =G22/E22 -> 0.86956522 | G22: 0.6 | H22: =B22*C22*E22*G22 -> 34.736256 | I22: =H22/B22 -> 0.31464
A23: Manufacturing | B23: =112*0.8 -> 89.6 | C23: 0.8 | D23: =E23/C23 -> 0.9375 | E23: 0.75 | F23: =G23/E23 -> 0.88 | G23: 0.66 | H23: =B23*C23*E23*G23 -> 35.4816 | I23: =H23/B23 -> 0.396
A24: Consume Goods | B24: =92*0.8 -> 73.6 | C24: 0.7 | D24: =E24/C24 -> 0.9322479 | E24: 0.65257353 | F24: =G24/E24 -> 0.87887324 | G24: 0.57352941 | H24: =B24*C24*E24*G24 -> 19.282396 | I24: =H24/B24 -> 0.26198908
A25: Transportation | B25: =58*0.8 -> 46.4 | C25: 0.68 | D25: =E25/C25 -> 0.88235294 | E25: 0.6 | F25: =G25/E25 -> 0.91666667 | G25: 0.55 | H25: =B25*C25*E25*G25 -> 10.41216 | I25: =H25/B25 -> 0.2244
A26: Oil and Gas | B26: =24*0.8 -> 19.2 | C26: 0.69 | D26: =E26/C26 -> 0.92753623 | E26: 0.64 | F26: =G26/E26 -> 0.9375 | G26: 0.6 | H26: =B26*C26*E26*G26 -> 5.087232 | I26: =H26/B26 -> 0.26496
A27: Average | B27: =average(B19:B26) -> 115.075 | C27: =average(C19:C26) -> 0.755 | D27: =average(D19:D26) -> 0.9203842 | E27: =average(E19:E26) -> 0.69532169 | F27: =average(F19:F26) -> 0.89833765 | G27: =average(G19:G26) -> 0.62419118 | H27: =average(H19:H26) -> 43.000939 | I27: =average(I19:I26) -> 0.33369675
A29: What industry has the best activation Funnel? Why? | C29: What industry has the worst activation Funnel? Why? | E29: What would you want to report to Marketing? | G29: Experiment Brief using Action, Outcome, Theory (Select 1 moments to improve)
